Traceback (most recent call last):
  File "/Users/valenetjong/qiskit/CCNN/main.py", line 169, in <module>
    main()
  File "/Users/valenetjong/qiskit/CCNN/main.py", line 165, in main
    session.test()
  File "/Users/valenetjong/qiskit/CCNN/main.py", line 109, in test
    model = self.model.load_state_dict(torch.load('/results/model.pth'))
  File "/Users/valenetjong/opt/anaconda3/envs/sklearn-env/lib/python3.9/site-packages/torch/serialization.py", line 594, in load
    with _open_file_like(f, 'rb') as opened_file:
  File "/Users/valenetjong/opt/anaconda3/envs/sklearn-env/lib/python3.9/site-packages/torch/serialization.py", line 230, in _open_file_like
    return _open_file(name_or_buffer, mode)
  File "/Users/valenetjong/opt/anaconda3/envs/sklearn-env/lib/python3.9/site-packages/torch/serialization.py", line 211, in __init__
    super(_open_file, self).__init__(open(name, mode))
FileNotFoundError: [Errno 2] No such file or directory: '/results/model.pth'